Workbook

Sheet テーブル仕様
A1: 実体名 | B1: テーブル名 | C1: 属性名 | D1: カラム名 | E1: データタイプ | F1: 桁数 | G1: 属性定義 | H1: PK | I1: 必須
A2: 星文化情報 | B2: star_culture | C2: 星文化ID | D2: star_culture_id | E2: bigint | F2: - | G2: 自動採番 | H2: ○ | I2: ○
A3: 星文化情報 | B3: star_culture | C3: 名称 | D3: name_ja | E3: varchar | F3: 32 | G3: 現代研究を踏まえた修正名称 | I3: ○ | K3: constellation.json | L3: name
A4: 星文化情報 | B4: star_culture | C4: 名称（英名） | D4: name_en | E4: varchar | F4: 64 | G4: 現代研究を踏まえた修正名称（英名）
A5: 星文化情報 | B5: star_culture | C5: 意味 | D5: meaning | E5: varchar | F5: 64 | G5: 現代研究を踏まえた修正意味 | K5: constellation.json | L5: description
A6: 星文化情報 | B6: star_culture | C6: =C14 -> 星座キー | D6: =D14 -> constellation_key | E6: =E14 -> varchar | F6: =F14 -> 32 | G6: D3-Celestial表示用キー | K6: constellation.json | L6: key
A7: 星文化情報 | B7: star_culture | C7: オリジナル名称 | D7: original_name_ja | E7: varchar | F7: 32 | G7: 出展元記載のオリジナル名称 | I7: ○
A8: 星文化情報 | B8: star_culture | C8: オリジナル名称（英名） | D8: original_name_en | E8: varchar | F8: 64 | G8: 出展元記載のオリジナル名称（英名）
A9: 星文化情報 | B9: star_culture | C9: オリジナル意味 | D9: original_meaning | E9: varchar | F9: 64 | G9: 出展元記載のオリジナル意味
A10: 星文化情報 | B10: star_culture | C10: メモ | D10: memo | E10: text | F10: -
A11: 星文化情報 | B11: star_culture | C11: 公開フラグ | D11: is_published | E11: boolean | F11: - | G11: true：公開、false：非公開（デフォルト：false） | I11: ○
A12: 星文化情報 | B12: star_culture | C12: 登録日時 | D12: created_at | E12: timestamp | F12: - | I12: ○
A13: 星文化情報 | B13: star_culture | C13: 更新日時 | D13: updated_at | E13: timestamp | F13: - | I13: ○
A14: 星座リスト | B14: constellation_list | C14: 星座キー | D14: constellation_key | E14: varchar | F14: 32 | H14: ○ | I14: ○
A15: 星座リスト | B15: constellation_list | C15: 赤経 | D15: ra | E15: numeric | F15: 4,1 | G15: 名前ラベル表示位置 | I15: ○ | K15: constellation.json | L15: ra
A16: 星座リスト | B16: constellation_list | C16: 赤緯 | D16: dec | E16: numeric | F16: 4,1 | G16: 名前ラベル表示位置 | I16: ○ | K16: constellation.json | L16: dec
A17: 星座リスト | B17: constellation_list | C17: メモ | D17: memo | E17: text | F17: -
A18: 星座リスト | B18: constellation_list | C18: 公開フラグ | D18: is_published | E18: boolean | F18: - | G18: true：公開、false：非公開（デフォルト：false） | I18: ○
A19: 星座リスト | B19: constellation_list | C19: 登録日時 | D19: created_at | E19: timestamp | F19: - | I19: ○
A20: 星座リスト | B20: constellation_list | C20: 更新日時 | D20: updated_at | E20: timestamp | F20: - | I20: ○
A21: 星座線リスト | B21: constellation_line_list | C21: =C14 -> 星座キー | D21: =D14 -> constellation_key | E21: =E14 -> varchar | F21: =F14 -> 32 | H21: ○ | I21: ○
A22: 星座線リスト | B22: constellation_line_list | C22: 線番 | D22: line_no | E22: integer | F22: - | G22: 星座線の組順序（1本目、2本目、、、） | H22: ○ | I22: ○ | K22: constellation.json | L22: lines
A23: 星座線リスト | B23: constellation_line_list | C23: 線順 | D23: point_no | E23: integer | F23: - | G23: 星座線を結ぶ恒星の順序（A→B→C→…） | H23: ○ | I23: ○ | K23: constellation.json | L23: lines
A24: 星座線リスト | B24: constellation_line_list | C24: =C26 -> 恒星 | D24: =D26 -> hipparcos | E24: =E26 -> varchar | F24: =F26 -> 10 | G24: =G26 -> ヒッパルコス星表番号 | I24: ○ | K24: constellation.json | L24: lines
A25: 星座線リスト | B25: constellation_line_list | C25: メモ | D25: memo | E25: text | F25: -
A26: 恒星マスタ | B26: star_master | C26: 恒星 | D26: hipparcos | E26: varchar | F26: 10 | G26: ヒッパルコス星表番号 | H26: ○ | I26: ○ | K26: star.json | L26: key
A27: 恒星マスタ | B27: star_master | C27: 赤経 | D27: ra | E27: numeric | F27: 14,11 | I27: ○ | K27: star.json | L27: ra
A28: 恒星マスタ | B28: star_master | C28: 赤緯 | D28: dec | E28: numeric | F28: 14,11 | I28: ○ | K28: star.json | L28: dec
A29: 恒星マスタ | B29: star_master | C29: メモ | D29: memo | E29: text | F29: -
A30: S地域リスト_星 | B30: s_area_list_c | C30: =C14 -> 星座キー | D30: =D14 -> constellation_key | E30: =E14 -> varchar | F30: =F14 -> 32 | H30: ○ | I30: ○
A31: S地域リスト_星 | B31: s_area_list_c | C31: S地域 | D31: s_area | E31: char | F31: 1 | G31: 1,2,3,4,5（末岡氏区分の地域Ⅰ～地域Ⅴ） | H31: ○ | I31: ○
A32: S地域リスト_星 | B32: s_area_list_c | C32: メモ | D32: memo | E32: text | F32: -
A33: 現代地域マスタ | B33: present_area_master | C33: 市町村 | D33: city | E33: varchar | F33: 16 | H33: ○ | I33: ○ | K33: city.json | L33: city
A34: 現代地域マスタ | B34: present_area_master | C34: 気象区分 | D34: forecast | E34: varchar | F34: 16 | G34: 上川中部、網走西部など | I34: ○ | K34: city.json | L34: forecast
A35: 現代地域マスタ | B35: present_area_master | C35: 地方区分 | D35: area | E35: varchar | F35: 16 | G35: 道央、道東など | I35: ○ | K35: city.json | L35: area
A36: 現代地域マスタ | B36: present_area_master | C36: 振興局 | D36: subprefecture | E36: varchar | F36: 16 | G36: 石狩、空知など | I36: ○ | K36: city.json | L36: subprefecture
A37: 現代地域マスタ | B37: present_area_master | C37: 緯度 | D37: lat | E37: numeric | F37: 9,6 | I37: ○ | K37: city.json | L37: lat
A38: 現代地域マスタ | B38: present_area_master | C38: 経度 | D38: lon | E38: numeric | F38: 9,6 | I38: ○ | K38: city.json | L38: lon
A39: 現代地域マスタ | B39: present_area_master | C39: メモ | D39: memo | E39: text | F39: -
A40: S地域リスト_地 | B40: s_area_list_p | C40: =C33 -> 市町村 | D40: =D33 -> city | E40: =E33 -> varchar | F40: =F33 -> 16 | H40: ○ | I40: ○
...

Sheet ddl
B1: 星座リスト | G1: =VLOOKUP(B1,テーブル仕様!A:B,2,FALSE) -> constellation_list | O1: ="create table "&G1&" (" -> create table constellation_list (
Q2: constellation_key | R2: varchar(32) | S2: not null
P3: , | Q3: ra | R3: numeric(4,1) | S3: not null
P4: , | Q4: dec | R4: numeric(4,1) | S4: not null
P5: , | Q5: memo | R5: text
P6: , | Q6: is_published | R6: boolean default false | S6: not null
P7: , | Q7: created_at | R7: timestamp default current_timestamp | S7: not null
P8: , | Q8: updated_at | R8: timestamp default current_timestamp | S8: not null
P9: , | Q9: primary key (constellation_key)
P10: );
B12: 星文化情報 | G12: =VLOOKUP(B12,テーブル仕様!A:B,2,FALSE) -> star_culture | O12: ="create table "&G12&" (" -> create table star_culture (
Q13: star_culture_id | R13: bigint | S13: not null
P14: , | Q14: name_ja | R14: varchar(32) | S14: not null
P15: , | Q15: name_en | R15: varchar(64)
P16: , | Q16: meaning | R16: varchar(64)
P17: , | Q17: constellation_key | R17: varchar(32)
P18: , | Q18: original_name_ja | R18: varchar(32) | S18: not null
P19: , | Q19: original_name_en | R19: varchar(64)
P20: , | Q20: original_meaning | R20: varchar(64)
P21: , | Q21: memo | R21: text
P22: , | Q22: is_published | R22: boolean default false | S22: not null
P23: , | Q23: created_at | R23: timestamp default current_timestamp | S23: not null
P24: , | Q24: updated_at | R24: timestamp default current_timestamp | S24: not null
P25: , | Q25: primary key (star_culture_id)
C26: 星座リスト | D26: 星座キー | H26: =VLOOKUP(C26,テーブル仕様!A:B,2,FALSE)&"."&VLOOKUP(D26,テーブル仕様!C:D,2,FALSE) -> constellation_list.constellation_key | P26: , | Q26: ="foreign key ("&VLOOKUP(D26,テーブル仕様!C:D,2,FALSE)&") references "&VLOOKUP(C26,テーブル仕様!A:B,2,FALSE)&" ("&VLOOKUP(D26,テーブル仕様!C:D,2,FALSE)&")" -> foreign key (constellation_key) references constellation_list (constellation_key)
P27: );
B29: 現代地域マスタ | G29: =VLOOKUP(B29,テーブル仕様!A:B,2,FALSE) -> present_area_master | O29: ="create table "&G29&" (" -> create table present_area_master (
Q30: city | R30: varchar(16) | S30: not null
P31: , | Q31: forecast | R31: varchar(16) | S31: not null
P32: , | Q32: area | R32: varchar(16) | S32: not null
P33: , | Q33: subprefecture | R33: varchar(16) | S33: not null
P34: , | Q34: lat | R34: numeric(9,6) | S34: not null
P35: , | Q35: lon | R35: numeric(9,6) | S35: not null
P36: , | Q36: memo | R36: text
P37: , | Q37: primary key (city)
P38: );
B40: 恒星マスタ | G40: =VLOOKUP(B40,テーブル仕様!A:B,2,FALSE) -> star_master | O40: ="create table "&G40&" (" -> create table star_master (
Q41: hipparcos | R41: varchar(10) | S41: not null
P42: , | Q42: ra | R42: numeric(14,11) | S42: not null
P43: , | Q43: dec | R43: numeric(14,11) | S43: not null
...
